<?xml version="1.0" ?>
<robot xmlns:xacro="http://ros.org/wiki/xacro">

  <xacro:macro name="pan_and_tilt" params="*origin">

    <joint name="pan" type="revolute">
      <axis xyz="0 0 1"/>
      <limit
        effort="2"
        lower="${-pi/2}"
        upper="${pi/2}"
        velocity="${pi}"/>
      <!--xacro:insert_block name="origin"/-->
      <origin rpy="0 0 0" xyz="0.01755 -0.00008 0.3975"/>
      <parent
        link="${robot_name}/camera_tower_link"/>
      <child
        link="${robot_name}/pan_link"/>
      <dynamics
        friction="0.1"
        damping="0.1"/>
    </joint>

    <link name="${robot_name}/pan_link">
      <visual>
        <origin
          rpy="0 0 0" 
          xyz="0 0 0"/> <!-- rpy= 0 0 ${pi/2}-->
        <geometry>
          <mesh
            filename="package://interbotix_xslocobot_descriptions/cmu_meshes/tilt_link.stl"
            scale="1 1 1"/> <!-- scale="0.001 0.001 0.001" -->
        </geometry>
        <material name="">
          <color rgba="0.250980392156863 0.250980392156863 0.250980392156863 1"/>
        </material>
      </visual>
      <collision>
        <origin
          rpy="0 0 0"
          xyz="0 0 0"/>
        <geometry>
          <mesh
            filename="package://interbotix_xslocobot_descriptions/cmu_meshes/tilt_link.stl"
            scale="1 1 1"/> <!-- scale="0.001 0.001 0.001" -->
        </geometry>
      </collision>
      <inertial>
            <origin rpy="0 0 0" xyz="-1.35308431126191E-16 -2.97071395261028E-17 0.0220876265081744"/>
            <mass value="0.0182769203076134"/>
            <inertia ixx="1.32243845065555E-05" ixy="5.07660179129181E-13" ixz="1.067515220067E-20" iyy="7.13386116649085E-06" iyz="-1.32882457845217E-20" izz="7.83291781352837E-06"/>
        </inertial>
    </link> 

    <gazebo reference="${robot_name}/pan_link">
      <material>Gazebo/DarkGrey</material>
      <self_collide>true</self_collide>
    </gazebo>

    <joint name="tilt" type="revolute">
      <axis xyz="0 1 0"/>
      <limit
        effort="1"
        lower="-1.57"
        upper="1.57"
        velocity="1"/>
      <origin
        rpy="0 0 0"
        xyz="0.0 0 0.05"/>
      <parent
        link="${robot_name}/pan_link"/>
      <child
        link="${robot_name}/tilt_link"/>
      <dynamics
        friction="0.1"
        damping="0.1"/>
    </joint>

    <xacro:if value="${hardware_type == 'gz_classic'}">
      <ros2_control name="camera_controller" type="system">
        <hardware>
          <plugin>gazebo_ros2_control/GazeboSystem</plugin>
        </hardware>
        <joint name="pan">
          <command_interface name="position">
            <param name="min">"${-pi/2}"</param>
            <param name="max">"${pi/2}"</param>
          </command_interface>
          <state_interface name="position"/>
        </joint>
        <joint name="tilt">
          <command_interface name="position">
            <param name="min">"${-pi/2}"</param>
            <param name="max">"${radians(75)}"</param>
          </command_interface>
          <state_interface name="position"/>
        </joint>
      </ros2_control>
    </xacro:if>

    <link name="${robot_name}/tilt_link">
      <visual>
        <origin
          rpy="0 0 0"
          xyz="0 0 0"/>
        <geometry>
          <mesh
            filename="package://interbotix_xslocobot_descriptions/cmu_meshes/roll_link.stl"
            scale="1 1 1"/>
        </geometry>
        <material name="">
            <color rgba="0.792156862745098 0.819607843137255 0.933333333333333 1"/>
        </material>
      </visual>
      <collision>
        <origin
          rpy="0 0 0"
          xyz="0 0 0"/>
        <geometry>
          <mesh
            filename="package://interbotix_xslocobot_descriptions/cmu_meshes/roll_link.stl"
            scale="1 1 1"/>
        </geometry>
      </collision>
      <inertial>
            <origin rpy="0 0 0" xyz="0.0168744200088311 -0.000442984145897884 -0.00405256422002387"/>
            <mass value="0.0547677687275323"/>
            <inertia ixx="1.07071738005716E-05" ixy="-1.46854788384565E-07" ixz="5.59529059364376E-08" iyy="1.77011620295824E-05" iyz="1.27587154712834E-09" izz="2.01583693170578E-05"/>
        </inertial>
    </link>

    <gazebo reference="${robot_name}/tilt_link">
      <material>Gazebo/DarkGrey</material>
      <self_collide>true</self_collide>
    </gazebo>

    <!-- Camera Model -->
    <joint name="camera" type="fixed">
      <origin
        rpy="0 0 0"
        xyz="0.06705 0.0 -0.00425"/>
      <parent
        link="${robot_name}/tilt_link"/>
      <child
        link="camera_${robot_name}_link"/>
    </joint>

    <gazebo reference="camera">
      <disableFixedJointLumping>true</disableFixedJointLumping>
    </gazebo>

    <link name="camera_${robot_name}_link">
      <visual>
        <origin
          rpy="0 0 0"
          xyz="0 0 0"/>
        <geometry>
          <mesh
            filename="package://interbotix_xslocobot_descriptions/cmu_meshes/camera_link.stl"
            scale="1 1 1"/>
        </geometry>
        <material name="">
          <color rgba="0.792156862745098 0.819607843137255 0.933333333333333 1"/>
        </material>
      </visual>
      <collision>
        <origin
          rpy="0 0 0"
          xyz="0 0 0"/>
        <geometry>
          <mesh
            filename="package://interbotix_xslocobot_descriptions/cmu_meshes/camera_link.stl"
            scale="1 1 1"/>
        </geometry>
      </collision>
      <inertial>
            <origin rpy="0 0 0" xyz="-0.0132722976093535 0.00168171470080143 2.49829664994428E-06"/>
            <mass value="0.0381925651163644"/>
            <inertia ixx="2.4688255642946E-05" ixy="1.60697655569215E-07" ixz="1.2993241737711E-08" iyy="3.66669176935806E-06" iyz="1.30215657011203E-08" izz="2.48602467766615E-05"/>
        </inertial>
    </link>

    <gazebo reference="camera_${robot_name}_link">
      <material>Gazebo/Grey</material>
      <self_collide>true</self_collide>
    </gazebo>

    <!-- Adds a dummy link, libgazebo_ros_openni_kinect publishes from frame's z-axis -->
    <!-- https://github.com/ros-simulation/gazebo_ros_pkgs/issues/243 -->
    <joint name="camera_depth_joint" type="fixed">
      <origin rpy="${-pi/2} 0 ${-pi/2}" xyz="0 0 0"/>
      <parent link="camera_${robot_name}_link"/>
      <child link="${robot_name}/camera_depth_link"/>
    </joint>
    <link name="${robot_name}/camera_depth_link">
      <origin rpy="0 0 0" xyz="0 0 0"/>
    </link>

    <gazebo reference="camera_${robot_name}_link">
      <sensor name="camera_frame_sensor" type="depth">
        <always_on>true</always_on>
        <update_rate>30.0</update_rate>
        <camera>
          <horizontal_fov>0.994837</horizontal_fov>
          <image>
            <format>R8G8B8</format>
            <width>640</width>
            <height>480</height>
          </image>
          <clip>
            <near>0.01</near>
            <far>10</far>
          </clip>
        </camera>
        <plugin filename="libgazebo_ros_camera.so" name="camera_frame_controller">
          <ros>
            <namespace>/$(arg robot_name)</namespace>
          </ros>
          <always_on>true</always_on>
          <update_rate>0.0</update_rate>
          <camera_name>camera</camera_name>
          <image_topic_name>color/image_raw</image_topic_name>
          <camera_info_topic_name>color/camera_info</camera_info_topic_name>
          <depth_image_topic_name>aligned_depth_to_color/image_raw</depth_image_topic_name>
          <depth_image_camera_info_topic_name>aligned_depth_to_color/camera_info</depth_image_camera_info_topic_name>
          <point_cloud_topic_name>depth_registered/points</point_cloud_topic_name>
          <frame_name>${robot_name}/camera_depth_link</frame_name>
          <point_cloud_cutoff>0.01</point_cloud_cutoff>
          <point_cloud_cutoff_max>10</point_cloud_cutoff_max>
          <distortion_k1>0.00000001</distortion_k1>
          <distortion_k2>0.00000001</distortion_k2>
          <distortion_k3>0.00000001</distortion_k3>
          <distortion_t1>0.00000001</distortion_t1>
          <distortion_t2>0.00000001</distortion_t2>
          <cx>0</cx>
          <cy>0</cy>
          <focal_length>0</focal_length>
          <hack_baseline>0</hack_baseline>
        </plugin>
      </sensor>
    </gazebo>

  </xacro:macro>

</robot>
